
ðŸ“… Buscando data: 2025-10-30 (Season: 2025)
   [DEBUG] ParÃ¢metros API: {'league': '1', 'season': '2025', 'date': '2025-10-30', 'status': 'NS'}
   [DEBUG] URL: https://v3.football.api-sports.io/fixtures
2025-10-31 02:34:23,495 - telegram.ext.Application - ERROR - No error handlers are registered, logging exception.
Traceback (most recent call last):
  File "/home/runner/workspace/.pythonlibs/lib/python3.11/site-packages/telegram/ext/_application.py", line 1315, in process_update
    await coroutine
  File "/home/runner/workspace/.pythonlibs/lib/python3.11/site-packages/telegram/ext/_handlers/basehandler.py", line 159, in handle_update
    return await self.callback(update, context)
           ^^^^^^^^^^^^^^^^^^^^^^^^^^^^^^^^^^^^
  File "/home/runner/workspace/main.py", line 1976, in button_handler
    ligas = await buscar_ligas_disponiveis_hoje()
            ^^^^^^^^^^^^^^^^^^^^^^^^^^^^^^^^^^^^^
  File "/home/runner/workspace/api_client.py", line 1318, in buscar_ligas_disponiveis_hoje
    jogos = await buscar_jogos_do_dia()
            ^^^^^^^^^^^^^^^^^^^^^^^^^^^
  File "/home/runner/workspace/api_client.py", line 615, in buscar_jogos_do_dia
    response = await api_request_with_retry("GET", API_URL + "fixtures", params=params)
               ^^^^^^^^^^^^^^^^^^^^^^^^^^^^^^^^^^^^^^^^^^^^^^^^^^^^^^^^^^^^^^^^^^^^^^^^
  File "/home/runner/workspace/.pythonlibs/lib/python3.11/site-packages/tenacity/asyncio/__init__.py", line 189, in async_wrapped
    return await copy(fn, *args, **kwargs)
           ^^^^^^^^^^^^^^^^^^^^^^^^^^^^^^^
  File "/home/runner/workspace/.pythonlibs/lib/python3.11/site-packages/tenacity/asyncio/__init__.py", line 111, in __call__
    do = await self.iter(retry_state=retry_state)
         ^^^^^^^^^^^^^^^^^^^^^^^^^^^^^^^^^^^^^^^^
  File "/home/runner/workspace/.pythonlibs/lib/python3.11/site-packages/tenacity/asyncio/__init__.py", line 153, in iter
    result = await action(retry_state)
             ^^^^^^^^^^^^^^^^^^^^^^^^^
  File "/home/runner/workspace/.pythonlibs/lib/python3.11/site-packages/tenacity/_utils.py", line 99, in inner
    return call(*args, **kwargs)
           ^^^^^^^^^^^^^^^^^^^^^
  File "/home/runner/workspace/.pythonlibs/lib/python3.11/site-packages/tenacity/__init__.py", line 400, in <lambda>
    self._add_action_func(lambda rs: rs.outcome.result())
                                     ^^^^^^^^^^^^^^^^^^^
  File "/nix/store/7d088dip86hlzri9sk0h78b63yfmx0a0-python3-3.11.13/lib/python3.11/concurrent/futures/_base.py", line 449, in result
    return self.__get_result()
           ^^^^^^^^^^^^^^^^^^^
  File "/nix/store/7d088dip86hlzri9sk0h78b63yfmx0a0-python3-3.11.13/lib/python3.11/concurrent/futures/_base.py", line 401, in __get_result
    raise self._exception
  File "/home/runner/workspace/.pythonlibs/lib/python3.11/site-packages/tenacity/asyncio/__init__.py", line 114, in __call__
    result = await fn(*args, **kwargs)
             ^^^^^^^^^^^^^^^^^^^^^^^^^
  File "/home/runner/workspace/api_client.py", line 86, in api_request_with_retry
    response = await client.request(method, url, **kwargs)
               ^^^^^^^^^^^^^^^^^^^^^^^^^^^^^^^^^^^^^^^^^^^
  File "/home/runner/workspace/.pythonlibs/lib/python3.11/site-packages/httpx/_client.py", line 1540, in request
    return await self.send(request, auth=auth, follow_redirects=follow_redirects)
           ^^^^^^^^^^^^^^^^^^^^^^^^^^^^^^^^^^^^^^^^^^^^^^^^^^^^^^^^^^^^^^^^^^^^^^
  File "/home/runner/workspace/.pythonlibs/lib/python3.11/site-packages/httpx/_client.py", line 1629, in send
    response = await self._send_handling_auth(
               ^^^^^^^^^^^^^^^^^^^^^^^^^^^^^^^
  File "/home/runner/workspace/.pythonlibs/lib/python3.11/site-packages/httpx/_client.py", line 1657, in _send_handling_auth
    response = await self._send_handling_redirects(
               ^^^^^^^^^^^^^^^^^^^^^^^^^^^^^^^^^^^^
  File "/home/runner/workspace/.pythonlibs/lib/python3.11/site-packages/httpx/_client.py", line 1694, in _send_handling_redirects
    response = await self._send_single_request(request)
               ^^^^^^^^^^^^^^^^^^^^^^^^^^^^^^^^^^^^^^^^
  File "/home/runner/workspace/.pythonlibs/lib/python3.11/site-packages/httpx/_client.py", line 1730, in _send_single_request
    response = await transport.handle_async_request(request)
               ^^^^^^^^^^^^^^^^^^^^^^^^^^^^^^^^^^^^^^^^^^^^^
  File "/home/runner/workspace/.pythonlibs/lib/python3.11/site-packages/httpx/_transports/default.py", line 394, in handle_async_request
    resp = await self._pool.handle_async_request(req)
           ^^^^^^^^^^^^^^^^^^^^^^^^^^^^^^^^^^^^^^^^^^
  File "/home/runner/workspace/.pythonlibs/lib/python3.11/site-packages/httpcore/_async/connection_pool.py", line 256, in handle_async_request
    raise exc from None
  File "/home/runner/workspace/.pythonlibs/lib/python3.11/site-packages/httpcore/_async/connection_pool.py", line 229, in handle_async_request
    await self._close_connections(closing)
  File "/home/runner/workspace/.pythonlibs/lib/python3.11/site-packages/httpcore/_async/connection_pool.py", line 345, in _close_connections
    await connection.aclose()
  File "/home/runner/workspace/.pythonlibs/lib/python3.11/site-packages/httpcore/_async/connection.py", line 173, in aclose
    await self._connection.aclose()
  File "/home/runner/workspace/.pythonlibs/lib/python3.11/site-packages/httpcore/_async/http11.py", line 258, in aclose
    await self._network_stream.aclose()
  File "/home/runner/workspace/.pythonlibs/lib/python3.11/site-packages/httpcore/_backends/anyio.py", line 53, in aclose
    await self._stream.aclose()
  File "/home/runner/workspace/.pythonlibs/lib/python3.11/site-packages/anyio/streams/tls.py", line 234, in aclose
    await self.transport_stream.aclose()
  File "/home/runner/workspace/.pythonlibs/lib/python3.11/site-packages/anyio/_backends/_asyncio.py", line 1323, in aclose
    self._transport.close()
  File "/nix/store/7d088dip86hlzri9sk0h78b63yfmx0a0-python3-3.11.13/lib/python3.11/asyncio/selector_events.py", line 864, in close
    self._loop.call_soon(self._call_connection_lost, None)
  File "/nix/store/7d088dip86hlzri9sk0h78b63yfmx0a0-python3-3.11.13/lib/python3.11/asyncio/base_events.py", line 762, in call_soon
    self._check_closed()
  File "/nix/store/7d088dip86hlzri9sk0h78b63yfmx0a0-python3-3.11.13/lib/python3.11/asyncio/base_events.py", line 520, in _check_closed
    raise RuntimeError('Event loop is closed')
RuntimeError: Event loop is closed